<?xml version="1.0" encoding="utf-8"?>
<robot name="nero_left_arm">
  <link name="dummy_link" />
  <joint name="base_to_dummy" type="fixed">
    <parent link="dummy_link" />
    <child link="base_link" />
    <origin xyz="-0.005 -0.125 0.0575" rpy="1.5708 0.0 3.14" />
  </joint>
  <link name="base_link">
    <inertial>
      <origin xyz="-0.00473641 2.56829e-05 0.0414515" rpy="0 0 0" />
      <mass value="1.02" />
      <inertia ixx="0.00267433" ixy="0" ixz="0" iyy="0.00282612" iyz="0" izz="0.00089624" />
    </inertial>
  </link>
  <joint name="joint1" type="revolute">
    <origin xyz="0.0 0.0 0.138" rpy="0.0 0.0 0.0" />
    <parent link="base_link" />
    <child link="link1" />
    <axis xyz="0 0 1" />
    <limit lower="-3.14" upper="3.14" effort="100" velocity="5" />
  </joint>
  <link name="link1">
    <inertial>
      <origin xyz="0.0001215 0.0001046 -0.00438" rpy="0 0 0" />
      <mass value="0.71" />
      <inertia ixx="0.00048916" ixy="0" ixz="0" iyy="0.00040472" iyz="0" izz="0.00043982" />
    </inertial>
  </link>
  <joint name="joint2" type="revolute">
    <origin xyz="0.0 0.0 0.0" rpy="-1.5707920841525134 9.333813216505504e-05 -3.1415926533917933" />
    <parent link="link1" />
    <child link="link2" />
    <axis xyz="0 0 1" />
    <limit lower="-3.14" upper="3.14" effort="100" velocity="5" />
  </joint>
  <link name="link2">
    <inertial>
      <origin xyz="0.19866 0.0109 0.00142" rpy="0 0 0" />
      <mass value="1.17" />
      <inertia ixx="0.0011691" ixy="0" ixz="0" iyy="0.067853" iyz="0" izz="0.067744" />
    </inertial>
  </link>
  <joint name="joint3" type="revolute">
    <origin xyz="0.0 -0.31 0.0" rpy="-1.5708005694372709 1.8000045898247663e-11 -3.1415841683050445" />
    <parent link="link2" />
    <child link="link3" />
    <axis xyz="0 0 1" />
    <limit lower="-3.14" upper="3.14" effort="100" velocity="5" />
  </joint>
  <link name="link3">
    <inertial>
      <origin xyz="-0.02027 -0.1339 -0.00045" rpy="0 0 0" />
      <mass value="0.5" />
      <inertia ixx="0.013617" ixy="0" ixz="0" iyy="0.0004502" iyz="0" izz="0.013803" />
    </inertial>
  </link>
  <joint name="joint4" type="revolute">
    <origin xyz="0.0 0.0 0.0" rpy="-1.5708005694372709 1.8000045898247663e-11 -3.1415841683050445" />
    <parent link="link3" />
    <child link="link4" />
    <axis xyz="0 0 1" />
    <limit lower="-3.14" upper="3.14" effort="100" velocity="5" />
  </joint>
  <link name="link4">
    <inertial>
      <origin xyz="-9.6e-05 0.00087 -0.00496" rpy="0 0 0" />
      <mass value="0.38" />
      <inertia ixx="0.00018501" ixy="0" ixz="0" iyy="0.00018965" iyz="0" izz="0.00015484" />
    </inertial>
  </link>
  <joint name="joint5" type="revolute">
    <origin xyz="0.0 -0.27001 0.0" rpy="-1.5707943268087745 -1.5707923267948967 -3.1415906535759155" />
    <parent link="link4" />
    <child link="link5" />
    <axis xyz="0 0 1" />
    <limit lower="-3.14" upper="3.14" effort="100" velocity="5" />
  </joint>
  <link name="link5">
    <inertial>
      <origin xyz="-4.1e-05 -0.0566 -0.0037" rpy="0 0 0" />
      <mass value="0.383" />
      <inertia ixx="0.00166169" ixy="0" ixz="0" iyy="0.0001851" iyz="0" izz="0.00164321" />
    </inertial>
  </link>
  <joint name="joint6" type="revolute">
    <origin xyz="0.0 0.0 0.0" rpy="-1.5707943268087745 -1.5707923267948967 -3.1415906535759155" />
    <parent link="link5" />
    <child link="link6" />
    <axis xyz="0 0 1" />
    <limit lower="-3.14" upper="3.14" effort="100" velocity="5" />
  </joint>
  <link name="link6">
    <inertial>
      <origin xyz="-8.8e-05 9e-06 -0.002" rpy="0 0 0" />
      <mass value="0.007" />
      <inertia ixx="5.73e-07" ixy="0" ixz="0" iyy="5.73e-07" iyz="0" izz="1.06e-06" />
    </inertial>
  </link>
  <joint name="joint7" type="revolute">
    <origin xyz="0.0 -0.0235 0.0" rpy="1.5708 0.0 -1.5708" />
    <parent link="link6" />
    <child link="link7" />
    <axis xyz="0 0 1" />
    <limit lower="-3.14" upper="3.14" effort="100" velocity="5" />
  </joint>
  <link name="link7">
    <inertial>
      <origin xyz="0.00065 -0.0491 0.0097" rpy="0 0 0" />
      <mass value="0.26" />
      <inertia ixx="0.001" ixy="0" ixz="0" iyy="0.0007" iyz="0" izz="0.0004" />
    </inertial>
  </link>
</robot>

