<?xml version="1.0" encoding="utf-8"?>
<robot name="nero_right_arm">
  <link name="dummy_link" />
  <!-- rpy matches nero-welded-base-and-lift.mjcf right_arm_base_link euler='-1.5708 0 4.7124'.
       Verified: Rx(-1.5708)@Ry(0)@Rz(4.7124) = Rz(0.321751)@Ry(-1.570785)@Rx(-1.892547) -->
  <joint name="base_to_dummy" type="fixed">
    <parent link="dummy_link" />
    <child link="base_link" />
    <origin xyz="-0.005 0.125 0.0575" rpy="-1.892547 -1.570785 0.321751" />
  </joint>
  <link name="base_link">
    <inertial>
      <origin xyz="-0.00963615 0.00016787 0.0448601" rpy="0 0 0" />
      <mass value="0.77" />
      <inertia ixx="0.0006669" ixy="0" ixz="0" iyy="0.00054501" iyz="0" izz="0.00051509" />
    </inertial>
  </link>
  <joint name="joint1" type="revolute">
    <origin xyz="0.0 0.0 0.138" rpy="0.0 0.0 0.0" />
    <parent link="base_link" />
    <child link="link1" />
    <axis xyz="0 0 1" />
    <limit lower="-3.14" upper="3.14" effort="100" velocity="5" />
  </joint>
  <link name="link1">
    <inertial>
      <origin xyz="-0.00077 -0.00006 -0.00686" rpy="0 0 0" />
      <mass value="0.77" />
      <inertia ixx="0.0006669" ixy="0" ixz="0" iyy="0.00054501" iyz="0" izz="0.00051509" />
    </inertial>
  </link>
  <joint name="joint2" type="revolute">
    <origin xyz="0.0 0.0 0.0" rpy="-1.5707920841525134 9.333813216505504e-05 -3.1415926533917933" />
    <parent link="link1" />
    <child link="link2" />
    <axis xyz="0 0 1" />
    <limit lower="-3.14" upper="3.14" effort="100" velocity="5" />
  </joint>
  <link name="link2">
    <inertial>
      <origin xyz="-0.00011 -0.06072 0.00148" rpy="0 0 0" />
      <mass value="0.49" />
      <inertia ixx="0.00053808" ixy="0" ixz="0" iyy="0.00029435" iyz="0" izz="0.00040266" />
    </inertial>
  </link>
  <joint name="joint3" type="revolute">
    <origin xyz="0.0 -0.31 0.0" rpy="-1.5708005694372709 1.8000045898247663e-11 -3.1415841683050445" />
    <parent link="link2" />
    <child link="link3" />
    <axis xyz="0 0 1" />
    <limit lower="-3.14" upper="3.14" effort="100" velocity="5" />
  </joint>
  <link name="link3">
    <inertial>
      <origin xyz="0.00014 0.00211 -0.04853" rpy="0 0 0" />
      <mass value="0.67" />
      <inertia ixx="0.00342528" ixy="0" ixz="0" iyy="0.0033924" iyz="0" izz="0.00026169" />
    </inertial>
  </link>
  <joint name="joint4" type="revolute">
    <origin xyz="0.0 0.0 0.0" rpy="-1.5708005694372709 1.8000045898247663e-11 -3.1415841683050445" />
    <parent link="link3" />
    <child link="link4" />
    <axis xyz="0 0 1" />
    <limit lower="-3.14" upper="3.14" effort="100" velocity="5" />
  </joint>
  <link name="link4">
    <inertial>
      <origin xyz="-0.00013 -0.05482 0.00132" rpy="0 0 0" />
      <mass value="0.41" />
      <inertia ixx="0.00031331" ixy="0" ixz="0" iyy="0.00013204" iyz="0" izz="0.0002393" />
    </inertial>
  </link>
  <joint name="joint5" type="revolute">
    <origin xyz="0.0 -0.27001 0.0" rpy="-1.5707943268087745 -1.5707923267948967 -3.1415906535759155" />
    <parent link="link4" />
    <child link="link5" />
    <axis xyz="0 0 1" />
    <limit lower="-3.14" upper="3.14" effort="100" velocity="5" />
  </joint>
  <link name="link5">
    <inertial>
      <origin xyz="0.00303 0.00617 -0.11778" rpy="0 0 0" />
      <mass value="0.56" />
      <inertia ixx="0.0008249" ixy="0" ixz="0" iyy="0.00078548" iyz="0" izz="0.00021015" />
    </inertial>
  </link>
  <joint name="joint6" type="revolute">
    <origin xyz="0.0 0.0 0.0" rpy="-1.5707943268087745 -1.5707923267948967 -3.1415906535759155" />
    <parent link="link5" />
    <child link="link6" />
    <axis xyz="0 0 1" />
    <limit lower="-3.14" upper="3.14" effort="100" velocity="5" />
  </joint>
  <link name="link6">
    <inertial>
      <origin xyz="0.00014 -0.0027 -0.00025" rpy="0 0 0" />
      <!-- ABSORBED gripper_base inertia (mass 0.0001, negligible) into link6 -->
      <mass value="0.3101" />
      <inertia ixx="0.00008181" ixy="0" ixz="0" iyy="0.00007176" iyz="0" izz="0.00007906" />
    </inertial>
  </link>
  <joint name="joint7" type="revolute">
    <origin xyz="0.0 -0.0235 0.0" rpy="1.5708 0.0 -1.5708" />
    <parent link="link6" />
    <child link="link7" />
    <axis xyz="0 0 1" />
    <limit lower="-3.14" upper="3.14" effort="100" velocity="5" />
  </joint>
  <link name="link7">
    <inertial>
      <origin xyz="-0.00014 -0.0001 -0.00275" rpy="0 0 0" />
      <mass value="0.000001" />
      <inertia ixx="1.1e-07" ixy="0" ixz="0" iyy="1.1e-07" iyz="0" izz="2e-07" />
    </inertial>
  </link>
</robot>

